Workbook

Sheet Dashboard
B2: PromptHalo — SOC 2 Common Criteria Gap Assessment
B3: 160 controls across CC1–CC9 · Version 2.0 · August 5, 2026 · Internal · Every figure on this tab is calculated — change a Score on any Controls tab and this updates.
B5: READINESS AT A GLANCE
B6: Controls in scope | C6: =COUNTIF('CC1 Controls'!$B$5:$B$39,"<>")+COUNTIF('CC2 Controls'!$B$5:$B$24,"<>")+COUNTIF('CC3 Controls'!$B$5:$B$28,"<>")+COUNTIF('CC4 Controls'!$B$5:$B$19,"<>")+COUNTIF('CC5 Controls'!$B$5:$B$19,"<>")+COUNTIF('CC6 Controls'!$B$5:$B$44,"<>")+COUNTIF('CC7 Controls'!$B$5:$B$30,"<>")+COUNTIF('CC8 Controls'!$B$5:$B$12,"<>")+COUNTIF('CC9 Controls'!$B$5:$B$16,"<>") -> 160 | D6: Every row on the nine Controls tabs.
B7: Applicable (N/A excluded) | C7: =((COUNTIF('CC1 Controls'!$B$5:$B$39,"<>")+COUNTIF('CC2 Controls'!$B$5:$B$24,"<>")+COUNTIF('CC3 Controls'!$B$5:$B$28,"<>")+COUNTIF('CC4 Controls'!$B$5:$B$19,"<>")+COUNTIF('CC5 Controls'!$B$5:$B$19,"<>")+COUNTIF('CC6 Controls'!$B$5:$B$44,"<>")+COUNTIF('CC7 Controls'!$B$5:$B$30,"<>")+COUNTIF('CC8 Controls'!$B$5:$B$12,"<>")+COUNTIF('CC9 Controls'!$B$5:$B$16,"<>")) - (COUNTIFS('CC1 Controls'!$B$5:$B$39,"<>",'CC1 Controls'!$J$5:$J$39,"N/A")+COUNTIFS('CC2 Controls'!$B$5:$B$24,"<>",'CC2 Controls'!$J$5:$J$24,"N/A")+COUNTIFS('CC3 Controls'!$B$5:$B$28,"<>",'CC3 Controls'!$J$5:$J$28,"N/A")+COUNTIFS('CC4 Controls'!$B$5:$B$19,"<>",'CC4 Controls'!$J$5:$J$19,"N/A")+COUNTIFS('CC5 Controls'!$B$5:$B$19,"<>",'CC5 Controls'!$J$5:$J$19,"N/A")+COUNTIFS('CC6 Controls'!$B$5:$B$44,"<>",'CC6 Controls'!$J$5:$J$44,"N/A")+COUNTIFS('CC7 Controls'!$B$5:$B$30,"<>",'CC7 Controls'!$J$5:$J$30,"N/A")+COUNTIFS('CC8 Controls'!$B$5:$B$12,"<>",'CC8 Controls'!$J$5:$J$12,"N/A")+COUNTIFS('CC9 Controls'!$B$5:$B$16,"<>",'CC9 Controls'!$J$5:$J$16,"N/A"))) -> 159 | D7: N/A rows are excluded from both the score and the maximum.
B8: Assessed | C8: =COUNTIFS('CC1 Controls'!$B$5:$B$39,"<>",'CC1 Controls'!$J$5:$J$39,">=0")+COUNTIFS('CC2 Controls'!$B$5:$B$24,"<>",'CC2 Controls'!$J$5:$J$24,">=0")+COUNTIFS('CC3 Controls'!$B$5:$B$28,"<>",'CC3 Controls'!$J$5:$J$28,">=0")+COUNTIFS('CC4 Controls'!$B$5:$B$19,"<>",'CC4 Controls'!$J$5:$J$19,">=0")+COUNTIFS('CC5 Controls'!$B$5:$B$19,"<>",'CC5 Controls'!$J$5:$J$19,">=0")+COUNTIFS('CC6 Controls'!$B$5:$B$44,"<>",'CC6 Controls'!$J$5:$J$44,">=0")+COUNTIFS('CC7 Controls'!$B$5:$B$30,"<>",'CC7 Controls'!$J$5:$J$30,">=0")+COUNTIFS('CC8 Controls'!$B$5:$B$12,"<>",'CC8 Controls'!$J$5:$J$12,">=0")+COUNTIFS('CC9 Controls'!$B$5:$B$16,"<>",'CC9 Controls'!$J$5:$J$16,">=0") -> 159 | D8: A blank Score is not a zero — it is reported separately below.
B9: Not yet assessed | C9: =((COUNTIF('CC1 Controls'!$B$5:$B$39,"<>")+COUNTIF('CC2 Controls'!$B$5:$B$24,"<>")+COUNTIF('CC3 Controls'!$B$5:$B$28,"<>")+COUNTIF('CC4 Controls'!$B$5:$B$19,"<>")+COUNTIF('CC5 Controls'!$B$5:$B$19,"<>")+COUNTIF('CC6 Controls'!$B$5:$B$44,"<>")+COUNTIF('CC7 Controls'!$B$5:$B$30,"<>")+COUNTIF('CC8 Controls'!$B$5:$B$12,"<>")+COUNTIF('CC9 Controls'!$B$5:$B$16,"<>")) - (COUNTIFS('CC1 Controls'!$B$5:$B$39,"<>",'CC1 Controls'!$J$5:$J$39,">=0")+COUNTIFS('CC2 Controls'!$B$5:$B$24,"<>",'CC2 Controls'!$J$5:$J$24,">=0")+COUNTIFS('CC3 Controls'!$B$5:$B$28,"<>",'CC3 Controls'!$J$5:$J$28,">=0")+COUNTIFS('CC4 Controls'!$B$5:$B$19,"<>",'CC4 Controls'!$J$5:$J$19,">=0")+COUNTIFS('CC5 Controls'!$B$5:$B$19,"<>",'CC5 Controls'!$J$5:$J$19,">=0")+COUNTIFS('CC6 Controls'!$B$5:$B$44,"<>",'CC6 Controls'!$J$5:$J$44,">=0")+COUNTIFS('CC7 Controls'!$B$5:$B$30,"<>",'CC7 Controls'!$J$5:$J$30,">=0")+COUNTIFS('CC8 Controls'!$B$5:$B$12,"<>",'CC8 Controls'!$J$5:$J$12,">=0")+COUNTIFS('CC9 Controls'!$B$5:$B$16,"<>",'CC9 Controls'!$J$5:$J$16,">=0"))) -> 1 | D9: Score these before relying on the readiness figure.
B10: Readiness | C10: =IFERROR((SUMIFS('CC1 Controls'!$J$5:$J$39,'CC1 Controls'!$B$5:$B$39,"<>")+SUMIFS('CC2 Controls'!$J$5:$J$24,'CC2 Controls'!$B$5:$B$24,"<>")+SUMIFS('CC3 Controls'!$J$5:$J$28,'CC3 Controls'!$B$5:$B$28,"<>")+SUMIFS('CC4 Controls'!$J$5:$J$19,'CC4 Controls'!$B$5:$B$19,"<>")+SUMIFS('CC5 Controls'!$J$5:$J$19,'CC5 Controls'!$B$5:$B$19,"<>")+SUMIFS('CC6 Controls'!$J$5:$J$44,'CC6 Controls'!$B$5:$B$44,"<>")+SUMIFS('CC7 Controls'!$J$5:$J$30,'CC7 Controls'!$B$5:$B$30,"<>")+SUMIFS('CC8 Controls'!$J$5:$J$12,'CC8 Controls'!$B$5:$B$12,"<>")+SUMIFS('CC9 Controls'!$J$5:$J$16,'CC9 Controls'!$B$5:$B$16,"<>"))/(((COUNTIF('CC1 Controls'!$B$5:$B$39,"<>")+COUNTIF('CC2 Controls'!$B$5:$B$24,"<>")+COUNTIF('CC3 Controls'!$B$5:$B$28,"<>")+COUNTIF('CC4 Controls'!$B$5:$B$19,"<>")+COUNTIF('CC5 Controls'!$B$5:$B$19,"<>")+COUNTIF('CC6 Controls'!$B$5:$B$44,"<>")+COUNTIF('CC7 Controls'!$B$5:$B$30,"<>")+COUNTIF('CC8 Controls'!$B$5:$B$12,"<>")+COUNTIF('CC9 Controls'!$B$5:$B$16,"<>")) - (COUNTIFS('CC1 Controls'!$B$5:$B$39,"<>",'CC1 Controls'!$J$5:$J$39,"N/A")+COUNTIFS('CC2 Controls'!$B$5:$B$24,"<>",'CC2 Controls'!$J$5:$J$24,"N/A")+COUNTIFS('CC3 Controls'!$B$5:$B$28,"<>",'CC3 Controls'!$J$5:$J$28,"N/A")+COUNTIFS('CC4 Controls'!$B$5:$B$19,"<>",'CC4 Controls'!$J$5:$J$19,"N/A")+COUNTIFS('CC5 Controls'!$B$5:$B$19,"<>",'CC5 Controls'!$J$5:$J$19,"N/A")+COUNTIFS('CC6 Controls'!$B$5:$B$44,"<>",'CC6 Controls'!$J$5:$J$44,"N/A")+COUNTIFS('CC7 Controls'!$B$5:$B$30,"<>",'CC7 Controls'!$J$5:$J$30,"N/A")+COUNTIFS('CC8 Controls'!$B$5:$B$12,"<>",'CC8 Controls'!$J$5:$J$12,"N/A")+COUNTIFS('CC9 Controls'!$B$5:$B$16,"<>",'CC9 Controls'!$J$5:$J$16,"N/A")))*4),0) -> 0.21855346 | D10: =REPT("|",ROUND(C10*100,0)) -> |||||||||||||||||||||| | E10: =TEXT(C10,"0.0%")&" of the maximum achievable score" -> 21.9% of the maximum achievable score
B11: Average level | C11: =IFERROR((SUMIFS('CC1 Controls'!$J$5:$J$39,'CC1 Controls'!$B$5:$B$39,"<>")+SUMIFS('CC2 Controls'!$J$5:$J$24,'CC2 Controls'!$B$5:$B$24,"<>")+SUMIFS('CC3 Controls'!$J$5:$J$28,'CC3 Controls'!$B$5:$B$28,"<>")+SUMIFS('CC4 Controls'!$J$5:$J$19,'CC4 Controls'!$B$5:$B$19,"<>")+SUMIFS('CC5 Controls'!$J$5:$J$19,'CC5 Controls'!$B$5:$B$19,"<>")+SUMIFS('CC6 Controls'!$J$5:$J$44,'CC6 Controls'!$B$5:$B$44,"<>")+SUMIFS('CC7 Controls'!$J$5:$J$30,'CC7 Controls'!$B$5:$B$30,"<>")+SUMIFS('CC8 Controls'!$J$5:$J$12,'CC8 Controls'!$B$5:$B$12,"<>")+SUMIFS('CC9 Controls'!$J$5:$J$16,'CC9 Controls'!$B$5:$B$16,"<>"))/(COUNTIFS('CC1 Controls'!$B$5:$B$39,"<>",'CC1 Controls'!$J$5:$J$39,">=0")+COUNTIFS('CC2 Controls'!$B$5:$B$24,"<>",'CC2 Controls'!$J$5:$J$24,">=0")+COUNTIFS('CC3 Controls'!$B$5:$B$28,"<>",'CC3 Controls'!$J$5:$J$28,">=0")+COUNTIFS('CC4 Controls'!$B$5:$B$19,"<>",'CC4 Controls'!$J$5:$J$19,">=0")+COUNTIFS('CC5 Controls'!$B$5:$B$19,"<>",'CC5 Controls'!$J$5:$J$19,">=0")+COUNTIFS('CC6 Controls'!$B$5:$B$44,"<>",'CC6 Controls'!$J$5:$J$44,">=0")+COUNTIFS('CC7 Controls'!$B$5:$B$30,"<>",'CC7 Controls'!$J$5:$J$30,">=0")+COUNTIFS('CC8 Controls'!$B$5:$B$12,"<>",'CC8 Controls'!$J$5:$J$12,">=0")+COUNTIFS('CC9 Controls'!$B$5:$B$16,"<>",'CC9 Controls'!$J$5:$J$16,">=0")),0) -> 0.87421384 | D11: Mean of the assessed rows only.
B12: Short of Type I (below level 2) | C12: =COUNTIFS('CC1 Controls'!$B$5:$B$39,"<>",'CC1 Controls'!$J$5:$J$39,"<2")+COUNTIFS('CC2 Controls'!$B$5:$B$24,"<>",'CC2 Controls'!$J$5:$J$24,"<2")+COUNTIFS('CC3 Controls'!$B$5:$B$28,"<>",'CC3 Controls'!$J$5:$J$28,"<2")+COUNTIFS('CC4 Controls'!$B$5:$B$19,"<>",'CC4 Controls'!$J$5:$J$19,"<2")+COUNTIFS('CC5 Controls'!$B$5:$B$19,"<>",'CC5 Controls'!$J$5:$J$19,"<2")+COUNTIFS('CC6 Controls'!$B$5:$B$44,"<>",'CC6 Controls'!$J$5:$J$44,"<2")+COUNTIFS('CC7 Controls'!$B$5:$B$30,"<>",'CC7 Controls'!$J$5:$J$30,"<2")+COUNTIFS('CC8 Controls'!$B$5:$B$12,"<>",'CC8 Controls'!$J$5:$J$12,"<2")+COUNTIFS('CC9 Controls'!$B$5:$B$16,"<>",'CC9 Controls'!$J$5:$J$16,"<2") -> 158 | D12: Design deficiencies. Each one fails a Type I.
B13: Short of Type II (below level 3) | C13: =COUNTIFS('CC1 Controls'!$B$5:$B$39,"<>",'CC1 Controls'!$J$5:$J$39,"<3")+COUNTIFS('CC2 Controls'!$B$5:$B$24,"<>",'CC2 Controls'!$J$5:$J$24,"<3")+COUNTIFS('CC3 Controls'!$B$5:$B$28,"<>",'CC3 Controls'!$J$5:$J$28,"<3")+COUNTIFS('CC4 Controls'!$B$5:$B$19,"<>",'CC4 Controls'!$J$5:$J$19,"<3")+COUNTIFS('CC5 Controls'!$B$5:$B$19,"<>",'CC5 Controls'!$J$5:$J$19,"<3")+COUNTIFS('CC6 Controls'!$B$5:$B$44,"<>",'CC6 Controls'!$J$5:$J$44,"<3")+COUNTIFS('CC7 Controls'!$B$5:$B$30,"<>",'CC7 Controls'!$J$5:$J$30,"<3")+COUNTIFS('CC8 Controls'!$B$5:$B$12,"<>",'CC8 Controls'!$J$5:$J$12,"<3")+COUNTIFS('CC9 Controls'!$B$5:$B$16,"<>",'CC9 Controls'!$J$5:$J$16,"<3") -> 159 | D13: Operating without retained evidence. Each one fails a Type II sample.
B15: SCORE DISTRIBUTION
B16: Level | C16: Controls | D16: Share | E16: Distribution
B17: 0 — Gap | C17: =COUNTIFS('CC1 Controls'!$B$5:$B$39,"<>",'CC1 Controls'!$J$5:$J$39,0)+COUNTIFS('CC2 Controls'!$B$5:$B$24,"<>",'CC2 Controls'!$J$5:$J$24,0)+COUNTIFS('CC3 Controls'!$B$5:$B$28,"<>",'CC3 Controls'!$J$5:$J$28,0)+COUNTIFS('CC4 Controls'!$B$5:$B$19,"<>",'CC4 Controls'!$J$5:$J$19,0)+COUNTIFS('CC5 Controls'!$B$5:$B$19,"<>",'CC5 Controls'!$J$5:$J$19,0)+COUNTIFS('CC6 Controls'!$B$5:$B$44,"<>",'CC6 Controls'!$J$5:$J$44,0)+COUNTIFS('CC7 Controls'!$B$5:$B$30,"<>",'CC7 Controls'!$J$5:$J$30,0)+COUNTIFS('CC8 Controls'!$B$5:$B$12,"<>",'CC8 Controls'!$J$5:$J$12,0)+COUNTIFS('CC9 Controls'!$B$5:$B$16,"<>",'CC9 Controls'!$J$5:$J$16,0) -> 21 | D17: =IFERROR(C17/$C$6,0) -> 0.13125 | E17: =REPT("|",ROUND(C17/$C$6*60,0)) -> ||||||||
B18: 1 — Documented | C18: =COUNTIFS('CC1 Controls'!$B$5:$B$39,"<>",'CC1 Controls'!$J$5:$J$39,1)+COUNTIFS('CC2 Controls'!$B$5:$B$24,"<>",'CC2 Controls'!$J$5:$J$24,1)+COUNTIFS('CC3 Controls'!$B$5:$B$28,"<>",'CC3 Controls'!$J$5:$J$28,1)+COUNTIFS('CC4 Controls'!$B$5:$B$19,"<>",'CC4 Controls'!$J$5:$J$19,1)+COUNTIFS('CC5 Controls'!$B$5:$B$19,"<>",'CC5 Controls'!$J$5:$J$19,1)+COUNTIFS('CC6 Controls'!$B$5:$B$44,"<>",'CC6 Controls'!$J$5:$J$44,1)+COUNTIFS('CC7 Controls'!$B$5:$B$30,"<>",'CC7 Controls'!$J$5:$J$30,1)+COUNTIFS('CC8 Controls'!$B$5:$B$12,"<>",'CC8 Controls'!$J$5:$J$12,1)+COUNTIFS('CC9 Controls'!$B$5:$B$16,"<>",'CC9 Controls'!$J$5:$J$16,1) -> 137 | D18: =IFERROR(C18/$C$6,0) -> 0.85625 | E18: =REPT("|",ROUND(C18/$C$6*60,0)) -> |||||||||||||||||||||||||||||||||||||||||||||||||||
B19: 2 — Implemented | C19: =COUNTIFS('CC1 Controls'!$B$5:$B$39,"<>",'CC1 Controls'!$J$5:$J$39,2)+COUNTIFS('CC2 Controls'!$B$5:$B$24,"<>",'CC2 Controls'!$J$5:$J$24,2)+COUNTIFS('CC3 Controls'!$B$5:$B$28,"<>",'CC3 Controls'!$J$5:$J$28,2)+COUNTIFS('CC4 Controls'!$B$5:$B$19,"<>",'CC4 Controls'!$J$5:$J$19,2)+COUNTIFS('CC5 Controls'!$B$5:$B$19,"<>",'CC5 Controls'!$J$5:$J$19,2)+COUNTIFS('CC6 Controls'!$B$5:$B$44,"<>",'CC6 Controls'!$J$5:$J$44,2)+COUNTIFS('CC7 Controls'!$B$5:$B$30,"<>",'CC7 Controls'!$J$5:$J$30,2)+COUNTIFS('CC8 Controls'!$B$5:$B$12,"<>",'CC8 Controls'!$J$5:$J$12,2)+COUNTIFS('CC9 Controls'!$B$5:$B$16,"<>",'CC9 Controls'!$J$5:$J$16,2) -> 1 | D19: =IFERROR(C19/$C$6,0) -> 0.00625 | E19: =REPT("|",ROUND(C19/$C$6*60,0))
B20: 3 — Evidenced | C20: =COUNTIFS('CC1 Controls'!$B$5:$B$39,"<>",'CC1 Controls'!$J$5:$J$39,3)+COUNTIFS('CC2 Controls'!$B$5:$B$24,"<>",'CC2 Controls'!$J$5:$J$24,3)+COUNTIFS('CC3 Controls'!$B$5:$B$28,"<>",'CC3 Controls'!$J$5:$J$28,3)+COUNTIFS('CC4 Controls'!$B$5:$B$19,"<>",'CC4 Controls'!$J$5:$J$19,3)+COUNTIFS('CC5 Controls'!$B$5:$B$19,"<>",'CC5 Controls'!$J$5:$J$19,3)+COUNTIFS('CC6 Controls'!$B$5:$B$44,"<>",'CC6 Controls'!$J$5:$J$44,3)+COUNTIFS('CC7 Controls'!$B$5:$B$30,"<>",'CC7 Controls'!$J$5:$J$30,3)+COUNTIFS('CC8 Controls'!$B$5:$B$12,"<>",'CC8 Controls'!$J$5:$J$12,3)+COUNTIFS('CC9 Controls'!$B$5:$B$16,"<>",'CC9 Controls'!$J$5:$J$16,3) -> 0 | D20: =IFERROR(C20/$C$6,0) -> 0 | E20: =REPT("|",ROUND(C20/$C$6*60,0))
B21: 4 — Automated | C21: =COUNTIFS('CC1 Controls'!$B$5:$B$39,"<>",'CC1 Controls'!$J$5:$J$39,4)+COUNTIFS('CC2 Controls'!$B$5:$B$24,"<>",'CC2 Controls'!$J$5:$J$24,4)+COUNTIFS('CC3 Controls'!$B$5:$B$28,"<>",'CC3 Controls'!$J$5:$J$28,4)+COUNTIFS('CC4 Controls'!$B$5:$B$19,"<>",'CC4 Controls'!$J$5:$J$19,4)+COUNTIFS('CC5 Controls'!$B$5:$B$19,"<>",'CC5 Controls'!$J$5:$J$19,4)+COUNTIFS('CC6 Controls'!$B$5:$B$44,"<>",'CC6 Controls'!$J$5:$J$44,4)+COUNTIFS('CC7 Controls'!$B$5:$B$30,"<>",'CC7 Controls'!$J$5:$J$30,4)+COUNTIFS('CC8 Controls'!$B$5:$B$12,"<>",'CC8 Controls'!$J$5:$J$12,4)+COUNTIFS('CC9 Controls'!$B$5:$B$16,"<>",'CC9 Controls'!$J$5:$J$16,4) -> 0 | D21: =IFERROR(C21/$C$6,0) -> 0 | E21: =REPT("|",ROUND(C21/$C$6*60,0))
B22: N/A — Not applicable | C22: =COUNTIFS('CC1 Controls'!$B$5:$B$39,"<>",'CC1 Controls'!$J$5:$J$39,"N/A")+COUNTIFS('CC2 Controls'!$B$5:$B$24,"<>",'CC2 Controls'!$J$5:$J$24,"N/A")+COUNTIFS('CC3 Controls'!$B$5:$B$28,"<>",'CC3 Controls'!$J$5:$J$28,"N/A")+COUNTIFS('CC4 Controls'!$B$5:$B$19,"<>",'CC4 Controls'!$J$5:$J$19,"N/A")+COUNTIFS('CC5 Controls'!$B$5:$B$19,"<>",'CC5 Controls'!$J$5:$J$19,"N/A")+COUNTIFS('CC6 Controls'!$B$5:$B$44,"<>",'CC6 Controls'!$J$5:$J$44,"N/A")+COUNTIFS('CC7 Controls'!$B$5:$B$30,"<>",'CC7 Controls'!$J$5:$J$30,"N/A")+COUNTIFS('CC8 Controls'!$B$5:$B$12,"<>",'CC8 Controls'!$J$5:$J$12,"N/A")+COUNTIFS('CC9 Controls'!$B$5:$B$16,"<>",'CC9 Controls'!$J$5:$J$16,"N/A") -> 1 | D22: =IFERROR(C22/$C$6,0) -> 0.00625 | E22: =REPT("|",ROUND(C22/$C$6*60,0))
B24: BY CRITERION
B25: Criterion | C25: Controls | D25: Assessed | E25: Average level | F25: At level 0 | G25: Below level 3 | H25: Policy: Yes | I25: Partial | J25: No
B26: CC1 Control Environment | C26: =COUNTIF('CC1 Controls'!$B$5:$B$39,"<>") -> 28 | D26: =COUNTIFS('CC1 Controls'!$B$5:$B$39,"<>",'CC1 Controls'!$J$5:$J$39,">=0") -> 27 | E26: =IFERROR(SUMIFS('CC1 Controls'!$J$5:$J$39,'CC1 Controls'!$B$5:$B$39,"<>")/COUNTIFS('CC1 Controls'!$B$5:$B$39,"<>",'CC1 Controls'!$J$5:$J$39,">=0"),0) -> 0.55555556 | F26: =COUNTIFS('CC1 Controls'!$B$5:$B$39,"<>",'CC1 Controls'!$J$5:$J$39,0) -> 13 | G26: =COUNTIFS('CC1 Controls'!$B$5:$B$39,"<>",'CC1 Controls'!$J$5:$J$39,"<3") -> 27 | H26: =COUNTIFS('CC1 Controls'!$B$5:$B$39,"<>",'CC1 Controls'!$O$5:$O$39,"Yes") -> 9 | I26: =COUNTIFS('CC1 Controls'!$B$5:$B$39,"<>",'CC1 Controls'!$O$5:$O$39,"Partial") -> 10 | J26: =COUNTIFS('CC1 Controls'!$B$5:$B$39,"<>",'CC1 Controls'!$O$5:$O$39,"No") -> 9
B27: CC2 Communication and Information | C27: =COUNTIF('CC2 Controls'!$B$5:$B$24,"<>") -> 17 | D27: =COUNTIFS('CC2 Controls'!$B$5:$B$24,"<>",'CC2 Controls'!$J$5:$J$24,">=0") -> 17 | E27: =IFERROR(SUMIFS('CC2 Controls'!$J$5:$J$24,'CC2 Controls'!$B$5:$B$24,"<>")/COUNTIFS('CC2 Controls'!$B$5:$B$24,"<>",'CC2 Controls'!$J$5:$J$24,">=0"),0) -> 0.70588235 | F27: =COUNTIFS('CC2 Controls'!$B$5:$B$24,"<>",'CC2 Controls'!$J$5:$J$24,0) -> 5 | G27: =COUNTIFS('CC2 Controls'!$B$5:$B$24,"<>",'CC2 Controls'!$J$5:$J$24,"<3") -> 17 | H27: =COUNTIFS('CC2 Controls'!$B$5:$B$24,"<>",'CC2 Controls'!$O$5:$O$24,"Yes") -> 10 | I27: =COUNTIFS('CC2 Controls'!$B$5:$B$24,"<>",'CC2 Controls'!$O$5:$O$24,"Partial") -> 4 | J27: =COUNTIFS('CC2 Controls'!$B$5:$B$24,"<>",'CC2 Controls'!$O$5:$O$24,"No") -> 3
B28: CC3 Risk Assessment | C28: =COUNTIF('CC3 Controls'!$B$5:$B$28,"<>") -> 20 | D28: =COUNTIFS('CC3 Controls'!$B$5:$B$28,"<>",'CC3 Controls'!$J$5:$J$28,">=0") -> 20 | E28: =IFERROR(SUMIFS('CC3 Controls'!$J$5:$J$28,'CC3 Controls'!$B$5:$B$28,"<>")/COUNTIFS('CC3 Controls'!$B$5:$B$28,"<>",'CC3 Controls'!$J$5:$J$28,">=0"),0) -> 0.9 | F28: =COUNTIFS('CC3 Controls'!$B$5:$B$28,"<>",'CC3 Controls'!$J$5:$J$28,0) -> 2 | G28: =COUNTIFS('CC3 Controls'!$B$5:$B$28,"<>",'CC3 Controls'!$J$5:$J$28,"<3") -> 20 | H28: =COUNTIFS('CC3 Controls'!$B$5:$B$28,"<>",'CC3 Controls'!$O$5:$O$28,"Yes") -> 14 | I28: =COUNTIFS('CC3 Controls'!$B$5:$B$28,"<>",'CC3 Controls'!$O$5:$O$28,"Partial") -> 4 | J28: =COUNTIFS('CC3 Controls'!$B$5:$B$28,"<>",'CC3 Controls'!$O$5:$O$28,"No") -> 2
B29: CC4 Monitoring Activities | C29: =COUNTIF('CC4 Controls'!$B$5:$B$19,"<>") -> 13 | D29: =COUNTIFS('CC4 Controls'!$B$5:$B$19,"<>",'CC4 Controls'!$J$5:$J$19,">=0") -> 13 | E29: =IFERROR(SUMIFS('CC4 Controls'!$J$5:$J$19,'CC4 Controls'!$B$5:$B$19,"<>")/COUNTIFS('CC4 Controls'!$B$5:$B$19,"<>",'CC4 Controls'!$J$5:$J$19,">=0"),0) -> 1 | F29: =COUNTIFS('CC4 Controls'!$B$5:$B$19,"<>",'CC4 Controls'!$J$5:$J$19,0) -> 0 | G29: =COUNTIFS('CC4 Controls'!$B$5:$B$19,"<>",'CC4 Controls'!$J$5:$J$19,"<3") -> 13 | H29: =COUNTIFS('CC4 Controls'!$B$5:$B$19,"<>",'CC4 Controls'!$O$5:$O$19,"Yes") -> 9 | I29: =COUNTIFS('CC4 Controls'!$B$5:$B$19,"<>",'CC4 Controls'!$O$5:$O$19,"Partial") -> 4 | J29: =COUNTIFS('CC4 Controls'!$B$5:$B$19,"<>",'CC4 Controls'!$O$5:$O$19,"No") -> 0
B30: CC5 Control Activities | C30: =COUNTIF('CC5 Controls'!$B$5:$B$19,"<>") -> 12 | D30: =COUNTIFS('CC5 Controls'!$B$5:$B$19,"<>",'CC5 Controls'!$J$5:$J$19,">=0") -> 12 | E30: =IFERROR(SUMIFS('CC5 Controls'!$J$5:$J$19,'CC5 Controls'!$B$5:$B$19,"<>")/COUNTIFS('CC5 Controls'!$B$5:$B$19,"<>",'CC5 Controls'!$J$5:$J$19,">=0"),0) -> 1 | F30: =COUNTIFS('CC5 Controls'!$B$5:$B$19,"<>",'CC5 Controls'!$J$5:$J$19,0) -> 0 | G30: =COUNTIFS('CC5 Controls'!$B$5:$B$19,"<>",'CC5 Controls'!$J$5:$J$19,"<3") -> 12 | H30: =COUNTIFS('CC5 Controls'!$B$5:$B$19,"<>",'CC5 Controls'!$O$5:$O$19,"Yes") -> 10 | I30: =COUNTIFS('CC5 Controls'!$B$5:$B$19,"<>",'CC5 Controls'!$O$5:$O$19,"Partial") -> 2 | J30: =COUNTIFS('CC5 Controls'!$B$5:$B$19,"<>",'CC5 Controls'!$O$5:$O$19,"No") -> 0
B31: CC6 Logical and Physical Access | C31: =COUNTIF('CC6 Controls'!$B$5:$B$44,"<>") -> 32 | D31: =COUNTIFS('CC6 Controls'!$B$5:$B$44,"<>",'CC6 Controls'!$J$5:$J$44,">=0") -> 32 | E31: =IFERROR(SUMIFS('CC6 Controls'!$J$5:$J$44,'CC6 Controls'!$B$5:$B$44,"<>")/COUNTIFS('CC6 Controls'!$B$5:$B$44,"<>",'CC6 Controls'!$J$5:$J$44,">=0"),0) -> 0.96875 | F31: =COUNTIFS('CC6 Controls'!$B$5:$B$44,"<>",'CC6 Controls'!$J$5:$J$44,0) -> 1 | G31: =COUNTIFS('CC6 Controls'!$B$5:$B$44,"<>",'CC6 Controls'!$J$5:$J$44,"<3") -> 32 | H31: =COUNTIFS('CC6 Controls'!$B$5:$B$44,"<>",'CC6 Controls'!$O$5:$O$44,"Yes") -> 31 | I31: =COUNTIFS('CC6 Controls'!$B$5:$B$44,"<>",'CC6 Controls'!$O$5:$O$44,"Partial") -> 0 | J31: =COUNTIFS('CC6 Controls'!$B$5:$B$44,"<>",'CC6 Controls'!$O$5:$O$44,"No") -> 1
B32: CC7 System Operations | C32: =COUNTIF('CC7 Controls'!$B$5:$B$30,"<>") -> 21 | D32: =COUNTIFS('CC7 Controls'!$B$5:$B$30,"<>",'CC7 Controls'!$J$5:$J$30,">=0") -> 21 | E32: =IFERROR(SUMIFS('CC7 Controls'!$J$5:$J$30,'CC7 Controls'!$B$5:$B$30,"<>")/COUNTIFS('CC7 Controls'!$B$5:$B$30,"<>",'CC7 Controls'!$J$5:$J$30,">=0"),0) -> 1 | F32: =COUNTIFS('CC7 Controls'!$B$5:$B$30,"<>",'CC7 Controls'!$J$5:$J$30,0) -> 0 | G32: =COUNTIFS('CC7 Controls'!$B$5:$B$30,"<>",'CC7 Controls'!$J$5:$J$30,"<3") -> 21 | H32: =COUNTIFS('CC7 Controls'!$B$5:$B$30,"<>",'CC7 Controls'!$O$5:$O$30,"Yes") -> 19 | I32: =COUNTIFS('CC7 Controls'!$B$5:$B$30,"<>",'CC7 Controls'!$O$5:$O$30,"Partial") -> 2 | J32: =COUNTIFS('CC7 Controls'!$B$5:$B$30,"<>",'CC7 Controls'!$O$5:$O$30,"No") -> 0
B33: CC8 Change Management | C33: =COUNTIF('CC8 Controls'!$B$5:$B$12,"<>") -> 7 | D33: =COUNTIFS('CC8 Controls'!$B$5:$B$12,"<>",'CC8 Controls'!$J$5:$J$12,">=0") -> 7 | E33: =IFERROR(SUMIFS('CC8 Controls'!$J$5:$J$12,'CC8 Controls'!$B$5:$B$12,"<>")/COUNTIFS('CC8 Controls'!$B$5:$B$12,"<>",'CC8 Controls'!$J$5:$J$12,">=0"),0) -> 1 | F33: =COUNTIFS('CC8 Controls'!$B$5:$B$12,"<>",'CC8 Controls'!$J$5:$J$12,0) -> 0 | G33: =COUNTIFS('CC8 Controls'!$B$5:$B$12,"<>",'CC8 Controls'!$J$5:$J$12,"<3") -> 7 | H33: =COUNTIFS('CC8 Controls'!$B$5:$B$12,"<>",'CC8 Controls'!$O$5:$O$12,"Yes") -> 7 | I33: =COUNTIFS('CC8 Controls'!$B$5:$B$12,"<>",'CC8 Controls'!$O$5:$O$12,"Partial") -> 0 | J33: =COUNTIFS('CC8 Controls'!$B$5:$B$12,"<>",'CC8 Controls'!$O$5:$O$12,"No") -> 0
B34: CC9 Risk Mitigation | C34: =COUNTIF('CC9 Controls'!$B$5:$B$16,"<>") -> 10 | D34: =COUNTIFS('CC9 Controls'!$B$5:$B$16,"<>",'CC9 Controls'!$J$5:$J$16,">=0") -> 10 | E34: =IFERROR(SUMIFS('CC9 Controls'!$J$5:$J$16,'CC9 Controls'!$B$5:$B$16,"<>")/COUNTIFS('CC9 Controls'!$B$5:$B$16,"<>",'CC9 Controls'!$J$5:$J$16,">=0"),0) -> 1 | F34: =COUNTIFS('CC9 Controls'!$B$5:$B$16,"<>",'CC9 Controls'!$J$5:$J$16,0) -> 0 | G34: =COUNTIFS('CC9 Controls'!$B$5:$B$16,"<>",'CC9 Controls'!$J$5:$J$16,"<3") -> 10 | H34: =COUNTIFS('CC9 Controls'!$B$5:$B$16,"<>",'CC9 Controls'!$O$5:$O$16,"Yes") -> 9 | I34: =COUNTIFS('CC9 Controls'!$B$5:$B$16,"<>",'CC9 Controls'!$O$5:$O$16,"Partial") -> 1 | J34: =COUNTIFS('CC9 Controls'!$B$5:$B$16,"<>",'CC9 Controls'!$O$5:$O$16,"No") -> 0
B35: All nine criteria | C35: =COUNTIF('CC1 Controls'!$B$5:$B$39,"<>")+COUNTIF('CC2 Controls'!$B$5:$B$24,"<>")+COUNTIF('CC3 Controls'!$B$5:$B$28,"<>")+COUNTIF('CC4 Controls'!$B$5:$B$19,"<>")+COUNTIF('CC5 Controls'!$B$5:$B$19,"<>")+COUNTIF('CC6 Controls'!$B$5:$B$44,"<>")+COUNTIF('CC7 Controls'!$B$5:$B$30,"<>")+COUNTIF('CC8 Controls'!$B$5:$B$12,"<>")+COUNTIF('CC9 Controls'!$B$5:$B$16,"<>") -> 160 | D35: =COUNTIFS('CC1 Controls'!$B$5:$B$39,"<>",'CC1 Controls'!$J$5:$J$39,">=0")+COUNTIFS('CC2 Controls'!$B$5:$B$24,"<>",'CC2 Controls'!$J$5:$J$24,">=0")+COUNTIFS('CC3 Controls'!$B$5:$B$28,"<>",'CC3 Controls'!$J$5:$J$28,">=0")+COUNTIFS('CC4 Controls'!$B$5:$B$19,"<>",'CC4 Controls'!$J$5:$J$19,">=0")+COUNTIFS('CC5 Controls'!$B$5:$B$19,"<>",'CC5 Controls'!$J$5:$J$19,">=0")+COUNTIFS('CC6 Controls'!$B$5:$B$44,"<>",'CC6 Controls'!$J$5:$J$44,">=0")+COUNTIFS('CC7 Controls'!$B$5:$B$30,"<>",'CC7 Controls'!$J$5:$J$30,">=0")+COUNTIFS('CC8 Controls'!$B$5:$B$12,"<>",'CC8 Controls'!$J$5:$J$12,">=0")+COUNTIFS('CC9 Controls'!$B$5:$B$16,"<>",'CC9 Controls'!$J$5:$J$16,">=0") -> 159 | E35: =IFERROR((SUMIFS('CC1 Controls'!$J$5:$J$39,'CC1 Controls'!$B$5:$B$39,"<>")+SUMIFS('CC2 Controls'!$J$5:$J$24,'CC2 Controls'!$B$5:$B$24,"<>")+SUMIFS('CC3 Controls'!$J$5:$J$28,'CC3 Controls'!$B$5:$B$28,"<>")+SUMIFS('CC4 Controls'!$J$5:$J$19,'CC4 Controls'!$B$5:$B$19,"<>")+SUMIFS('CC5 Controls'!$J$5:$J$19,'CC5 Controls'!$B$5:$B$19,"<>")+SUMIFS('CC6 Controls'!$J$5:$J$44,'CC6 Controls'!$B$5:$B$44,"<>")+SUMIFS('CC7 Controls'!$J$5:$J$30,'CC7 Controls'!$B$5:$B$30,"<>")+SUMIFS('CC8 Controls'!$J$5:$J$12,'CC8 Controls'!$B$5:$B$12,"<>")+SUMIFS('CC9 Controls'!$J$5:$J$16,'CC9 Controls'!$B$5:$B$16,"<>"))/(COUNTIFS('CC1 Controls'!$B$5:$B$39,"<>",'CC1 Controls'!$J$5:$J$39,">=0")+COUNTIFS('CC2 Controls'!$B$5:$B$24,"<>",'CC2 Controls'!$J$5:$J$24,">=0")+COUNTIFS('CC3 Controls'!$B$5:$B$28,"<>",'CC3 Controls'!$J$5:$J$28,">=0")+COUNTIFS('CC4 Controls'!$B$5:$B$19,"<>",'CC4 Controls'!$J$5:$J$19,">=0")+COUNTIFS('CC5 Controls'!$B$5:$B$19,"<>",'CC5 Controls'!$J$5:$J$19,">=0")+COUNTIFS('CC6 Controls'!$B$5:$B$44,"<>",'CC6 Controls'!$J$5:$J$44,">=0")+COUNTIFS('CC7 Controls'!$B$5:$B$30,"<>",'CC7 Controls'!$J$5:$J$30,">=0")+COUNTIFS('CC8 Controls'!$B$5:$B$12,"<>",'CC8 Controls'!$J$5:$J$12,">=0")+COUNTIFS('CC9 Controls'!$B$5:$B$16,"<>",'CC9 Controls'!$J$5:$J$16,">=0")),0) -> 0.87421384 | F35: =COUNTIFS('CC1 Controls'!$B$5:$B$39,"<>",'CC1 Controls'!$J$5:$J$39,0)+COUNTIFS('CC2 Controls'!$B$5:$B$24,"<>",'CC2 Controls'!$J$5:$J$24,0)+COUNTIFS('CC3 Controls'!$B$5:$B$28,"<>",'CC3 Controls'!$J$5:$J$28,0)+COUNTIFS('CC4 Controls'!$B$5:$B$19,"<>",'CC4 Controls'!$J$5:$J$19,0)+COUNTIFS('CC5 Controls'!$B$5:$B$19,"<>",'CC5 Controls'!$J$5:$J$19,0)+COUNTIFS('CC6 Controls'!$B$5:$B$44,"<>",'CC6 Controls'!$J$5:$J$44,0)+COUNTIFS('CC7 Controls'!$B$5:$B$30,"<>",'CC7 Controls'!$J$5:$J$30,0)+COUNTIFS('CC8 Controls'!$B$5:$B$12,"<>",'CC8 Controls'!$J$5:$J$12,0)+COUNTIFS('CC9 Controls'!$B$5:$B$16,"<>",'CC9 Controls'!$J$5:$J$16,0) -> 21 | G35: =COUNTIFS('CC1 Controls'!$B$5:$B$39,"<>",'CC1 Controls'!$J$5:$J$39,"<3")+COUNTIFS('CC2 Controls'!$B$5:$B$24,"<>",'CC2 Controls'!$J$5:$J$24,"<3")+COUNTIFS('CC3 Controls'!$B$5:$B$28,"<>",'CC3 Controls'!$J$5:$J$28,"<3")+COUNTIFS('CC4 Controls'!$B$5:$B$19,"<>",'CC4 Controls'!$J$5:$J$19,"<3")+COUNTIFS('CC5 Controls'!$B$5:$B$19,"<>",'CC5 Controls'!$J$5:$J$19,"<3")+COUNTIFS('CC6 Controls'!$B$5:$B$44,"<>",'CC6 Controls'!$J$5:$J$44,"<3")+COUNTIFS('CC7 Controls'!$B$5:$B$30,"<>",'CC7 Controls'!$J$5:$J$30,"<3")+COUNTIFS('CC8 Controls'!$B$5:$B$12,"<>",'CC8 Controls'!$J$5:$J$12,"<3")+COUNTIFS('CC9 Controls'!$B$5:$B$16,"<>",'CC9 Controls'!$J$5:$J$16,"<3") -> 159 | H35: =COUNTIFS('CC1 Controls'!$B$5:$B$39,"<>",'CC1 Controls'!$O$5:$O$39,"Yes")+COUNTIFS('CC2 Controls'!$B$5:$B$24,"<>",'CC2 Controls'!$O$5:$O$24,"Yes")+COUNTIFS('CC3 Controls'!$B$5:$B$28,"<>",'CC3 Controls'!$O$5:$O$28,"Yes")+COUNTIFS('CC4 Controls'!$B$5:$B$19,"<>",'CC4 Controls'!$O$5:$O$19,"Yes")+COUNTIFS('CC5 Controls'!$B$5:$B$19,"<>",'CC5 Controls'!$O$5:$O$19,"Yes")+COUNTIFS('CC6 Controls'!$B$5:$B$44,"<>",'CC6 Controls'!$O$5:$O$44,"Yes")+COUNTIFS('CC7 Controls'!$B$5:$B$30,"<>",'CC7 Controls'!$O$5:$O$30,"Yes")+COUNTIFS('CC8 Controls'!$B$5:$B$12,"<>",'CC8 Controls'!$O$5:$O$12,"Yes")+COUNTIFS('CC9 Controls'!$B$5:$B$16,"<>",'CC9 Controls'!$O$5:$O$16,"Yes") -> 118 | I35: =COUNTIFS('CC1 Controls'!$B$5:$B$39,"<>",'CC1 Controls'!$O$5:$O$39,"Partial")+COUNTIFS('CC2 Controls'!$B$5:$B$24,"<>",'CC2 Controls'!$O$5:$O$24,"Partial")+COUNTIFS('CC3 Controls'!$B$5:$B$28,"<>",'CC3 Controls'!$O$5:$O$28,"Partial")+COUNTIFS('CC4 Controls'!$B$5:$B$19,"<>",'CC4 Controls'!$O$5:$O$19,"Partial")+COUNTIFS('CC5 Controls'!$B$5:$B$19,"<>",'CC5 Controls'!$O$5:$O$19,"Partial")+COUNTIFS('CC6 Controls'!$B$5:$B$44,"<>",'CC6 Controls'!$O$5:$O$44,"Partial")+COUNTIFS('CC7 Controls'!$B$5:$B$30,"<>",'CC7 Controls'!$O$5:$O$30,"Partial")+COUNTIFS('CC8 Controls'!$B$5:$B$12,"<>",'CC8 Controls'!$O$5:$O$12,"Partial")+COUNTIFS('CC9 Controls'!$B$5:$B$16,"<>",'CC9 Controls'!$O$5:$O$16,"Partial") -> 27 | J35: =COUNTIFS('CC1 Controls'!$B$5:$B$39,"<>",'CC1 Controls'!$O$5:$O$39,"No")+COUNTIFS('CC2 Controls'!$B$5:$B$24,"<>",'CC2 Controls'!$O$5:$O$24,"No")+COUNTIFS('CC3 Controls'!$B$5:$B$28,"<>",'CC3 Controls'!$O$5:$O$28,"No")+COUNTIFS('CC4 Controls'!$B$5:$B$19,"<>",'CC4 Controls'!$O$5:$O$19,"No")+COUNTIFS('CC5 Controls'!$B$5:$B$19,"<>",'CC5 Controls'!$O$5:$O$19,"No")+COUNTIFS('CC6 Controls'!$B$5:$B$44,"<>",'CC6 Controls'!$O$5:$O$44,"No")+COUNTIFS('CC7 Controls'!$B$5:$B$30,"<>",'CC7 Controls'!$O$5:$O$30,"No")+COUNTIFS('CC8 Controls'!$B$5:$B$12,"<>",'CC8 Controls'!$O$5:$O$12,"No")+COUNTIFS('CC9 Controls'!$B$5:$B$16,"<>",'CC9 Controls'!$O$5:$O$16,"No") -> 15
B38: OPEN GAPS — CONTROLS ASSESSED AT LEVEL 0 (21 of 160)
B39: Status is live: rescore the control on its tab and this column changes.
B40: Control | C40: Live status | D40: What is missing
B41: CC1.1-01 | C41: =IF('CC1 Controls'!J6=0,"Open",IF('CC1 Controls'!J6="","Not scored","Now level "&'CC1 Controls'!J6)) -> Open | D41: Code of Conduct (POL-COC-001) approved by the Steering Committee and published to all personnel.
B42: CC1.1-02 | C42: =IF('CC1 Controls'!J7=0,"Open",IF('CC1 Controls'!J7="","Not scored","Now level "&'CC1 Controls'!J7)) -> Open | D42: Every employee and contractor accepts the Code of Conduct at onboarding, on material revision, and annually.
B43: CC1.1-03 | C43: =IF('CC1 Controls'!J8=0,"Open",IF('CC1 Controls'!J8="","Not scored","Now level "&'CC1 Controls'!J8)) -> Open | D43: Conflict of interest declaration completed annually and whenever a new client engagement is accepted.
B44: CC1.1-04 | C44: =IF('CC1 Controls'!J9=0,"Open",IF('CC1 Controls'!J9="","Not scored","Now level "&'CC1 Controls'!J9)) -> Open | D44: Ethics reporting channel that bypasses the Security Officer, with anti-retaliation stated.
B45: CC1.1-05 | C45: =IF('CC1 Controls'!J10=0,"Open",IF('CC1 Controls'!J10="","Not scored","Now level "&'CC1 Controls'!J10)) -> Open | D45: Conduct deviations are documented with the finding, the decision and the rationale.
B46: CC1.2-06 | C46: =IF('CC1 Controls'!J19=0,"Open",IF('CC1 Controls'!J19="","Not scored","Now level "&'CC1 Controls'!J19)) -> Open | D46: Committee composition is reviewed as the Company grows and additional members are appointed when available.
...

Sheet Read Me
B2: PromptHalo — SOC 2 Common Criteria Control Plan (CC1–CC9)
B3: POL-ISP-001 supporting workbook · Version 2.1 · August 6, 2026 · Internal
B5: HOW TO USE THIS WORKBOOK
B6: Controls tabs | D6: Nine tabs in identical format covering the whole of the Common Criteria — 28 controls across CC1, 17 across CC2, 20 across CC3, 13 across CC4, 12 across CC5, 32 across CC6, 21 across CC7, 7 across CC8 and 10 across CC9, 160 in all — grouped so each criterion collapses to a single row. Use the outline buttons in the left margin. Fill in the shaded columns only: Owner, Score and Next due. On CC1 and CC2 columns O to Q assess the implementation plans; on CC3 to CC9 they assess the approved policy library, and the headers say which. The Dashboard tab summarises every figure below.
B7: Setup | D7: One-time Secureframe, Google Workspace, GitHub and AWS configuration, forty-four steps. Steps 1 to 13 switch on CC1; 14 to 20 cover CC2; 21 to 26 CC3; 27 to 30 CC4; 31 to 36 CC5 and CC6; 37 to 44 CC7, CC8 and CC9. From step 21 onward every step is written against a clause the approved policies already contain, so none of them asks you to rewrite policy you have.
B8: Governance Log | D8: The single log that satisfies CC1.2-02 (decisions recorded), CC1.3-04 (delegations), CC2.3-05 (commitments reviewed before they are made) and CC3.2-06 (risk acceptances). One line per decision, with the control reference so it traces back to a row on any controls tab.
B9: Calendar | D9: Seven scheduled events, six event-driven triggers, and one row for what runs continuously. All 160 controls appear at least once, so the Calendar is the coverage check: if these operate, the plan has operated for the year.
B11: THE SIMPLIFICATION
B12: Six artifacts | D12: 1. Policy repository (GitHub) 2. Acknowledgment register (Secureframe) 3. Governance Log (this workbook) 4. Onboarding checklist (Secureframe) 5. Control matrix (Secureframe) 6. Annual Assessment (signed Word document) 7. Risk register (Secureframe) 8. Annual risk assessment with fraud section (Word document) 9. Plan of action — the single deficiency population (Secureframe)
B13: Seven events | D13: Onboarding (per hire) · Monthly evaluation cycle · Quarterly evaluation cycle · Quarterly Committee report · Annual acknowledgment and training cycle · Annual risk assessment · Annual assessment and policy review. Plus four triggers that fire on an event rather than a date.
B14: Division of labour | D14: Secureframe owns anything involving a person: policy acceptance, training, screening, onboarding. GitHub owns anything that is a document: policy text, version history, approval trail. Nothing lives in email or in a local folder.
B16: THE ONE THING TO FIX
B17: CC1.2 independence | D17: With a CEO-only Steering Committee you cannot fully satisfy CC1.2. The ISP records this as a documented limitation with a compensating control, which is defensible. Recruiting one unpaid outside advisor to sign an annual oversight memo (CC1.2-05) converts a permanent scope limitation into a satisfied criterion for the cost of one meeting a year.
B21: GAP ASSESSMENT SCALE | D21: Score each control 0–4 in the Score column of its Controls tab. A Type I report needs every control at 2 or above; a Type II needs 3 or above, sustained across the observation period. CC3 to CC6 were scored from the approved policy library, which caps them at 1 until the controls are shown operating.
B23: N/A — Not applicable | D23: The control does not apply to the Company. Excluded from both the score and the maximum, so it does not distort readiness. Record the reason in the Governance Log — an auditor will ask why.
B24: 0 — Gap | D24: Nothing in place. The control is neither written down nor operating.
B25: 1 — Documented | D25: Written into an approved policy or procedure, but not yet operating in practice. Design only.
B26: 2 — Implemented | D26: Operating in practice, but evidence is not consistently produced or retained. Sufficient for a Type I; will fail a Type II sample.
B27: 3 — Evidenced | D27: Operating with dated evidence retained for every occurrence, sufficient for an auditor to sample across the observation period.
B28: 4 — Automated | D28: Evidence is produced and retained continuously by a system without manual effort, and drift is detected without anyone checking.
B30: Not scored | D30: Leave the Score cell blank until the control has been assessed. A blank is reported separately below and is not treated as a zero.
B32: SCORE SUMMARY
B33: Total controls | C33: =COUNTIF('CC1 Controls'!$B$5:$B$39,"<>")+COUNTIF('CC2 Controls'!$B$5:$B$24,"<>")+COUNTIF('CC3 Controls'!$B$5:$B$28,"<>")+COUNTIF('CC4 Controls'!$B$5:$B$19,"<>")+COUNTIF('CC5 Controls'!$B$5:$B$19,"<>")+COUNTIF('CC6 Controls'!$B$5:$B$44,"<>")+COUNTIF('CC7 Controls'!$B$5:$B$30,"<>")+COUNTIF('CC8 Controls'!$B$5:$B$12,"<>")+COUNTIF('CC9 Controls'!$B$5:$B$16,"<>") -> 160
B34: Not applicable | C34: =COUNTIFS('CC1 Controls'!$B$5:$B$39,"<>",'CC1 Controls'!$J$5:$J$39,"N/A")+COUNTIFS('CC2 Controls'!$B$5:$B$24,"<>",'CC2 Controls'!$J$5:$J$24,"N/A")+COUNTIFS('CC3 Controls'!$B$5:$B$28,"<>",'CC3 Controls'!$J$5:$J$28,"N/A")+COUNTIFS('CC4 Controls'!$B$5:$B$19,"<>",'CC4 Controls'!$J$5:$J$19,"N/A")+COUNTIFS('CC5 Controls'!$B$5:$B$19,"<>",'CC5 Controls'!$J$5:$J$19,"N/A")+COUNTIFS('CC6 Controls'!$B$5:$B$44,"<>",'CC6 Controls'!$J$5:$J$44,"N/A")+COUNTIFS('CC7 Controls'!$B$5:$B$30,"<>",'CC7 Controls'!$J$5:$J$30,"N/A")+COUNTIFS('CC8 Controls'!$B$5:$B$12,"<>",'CC8 Controls'!$J$5:$J$12,"N/A")+COUNTIFS('CC9 Controls'!$B$5:$B$16,"<>",'CC9 Controls'!$J$5:$J$16,"N/A") -> 1
B35: Applicable controls | C35: =((COUNTIF('CC1 Controls'!$B$5:$B$39,"<>")+COUNTIF('CC2 Controls'!$B$5:$B$24,"<>")+COUNTIF('CC3 Controls'!$B$5:$B$28,"<>")+COUNTIF('CC4 Controls'!$B$5:$B$19,"<>")+COUNTIF('CC5 Controls'!$B$5:$B$19,"<>")+COUNTIF('CC6 Controls'!$B$5:$B$44,"<>")+COUNTIF('CC7 Controls'!$B$5:$B$30,"<>")+COUNTIF('CC8 Controls'!$B$5:$B$12,"<>")+COUNTIF('CC9 Controls'!$B$5:$B$16,"<>")) - (COUNTIFS('CC1 Controls'!$B$5:$B$39,"<>",'CC1 Controls'!$J$5:$J$39,"N/A")+COUNTIFS('CC2 Controls'!$B$5:$B$24,"<>",'CC2 Controls'!$J$5:$J$24,"N/A")+COUNTIFS('CC3 Controls'!$B$5:$B$28,"<>",'CC3 Controls'!$J$5:$J$28,"N/A")+COUNTIFS('CC4 Controls'!$B$5:$B$19,"<>",'CC4 Controls'!$J$5:$J$19,"N/A")+COUNTIFS('CC5 Controls'!$B$5:$B$19,"<>",'CC5 Controls'!$J$5:$J$19,"N/A")+COUNTIFS('CC6 Controls'!$B$5:$B$44,"<>",'CC6 Controls'!$J$5:$J$44,"N/A")+COUNTIFS('CC7 Controls'!$B$5:$B$30,"<>",'CC7 Controls'!$J$5:$J$30,"N/A")+COUNTIFS('CC8 Controls'!$B$5:$B$12,"<>",'CC8 Controls'!$J$5:$J$12,"N/A")+COUNTIFS('CC9 Controls'!$B$5:$B$16,"<>",'CC9 Controls'!$J$5:$J$16,"N/A"))) -> 159
B36: Controls scored | C36: =COUNTIFS('CC1 Controls'!$B$5:$B$39,"<>",'CC1 Controls'!$J$5:$J$39,">=0")+COUNTIFS('CC2 Controls'!$B$5:$B$24,"<>",'CC2 Controls'!$J$5:$J$24,">=0")+COUNTIFS('CC3 Controls'!$B$5:$B$28,"<>",'CC3 Controls'!$J$5:$J$28,">=0")+COUNTIFS('CC4 Controls'!$B$5:$B$19,"<>",'CC4 Controls'!$J$5:$J$19,">=0")+COUNTIFS('CC5 Controls'!$B$5:$B$19,"<>",'CC5 Controls'!$J$5:$J$19,">=0")+COUNTIFS('CC6 Controls'!$B$5:$B$44,"<>",'CC6 Controls'!$J$5:$J$44,">=0")+COUNTIFS('CC7 Controls'!$B$5:$B$30,"<>",'CC7 Controls'!$J$5:$J$30,">=0")+COUNTIFS('CC8 Controls'!$B$5:$B$12,"<>",'CC8 Controls'!$J$5:$J$12,">=0")+COUNTIFS('CC9 Controls'!$B$5:$B$16,"<>",'CC9 Controls'!$J$5:$J$16,">=0") -> 159
B37: Not yet scored | C37: =((COUNTIF('CC1 Controls'!$B$5:$B$39,"<>")+COUNTIF('CC2 Controls'!$B$5:$B$24,"<>")+COUNTIF('CC3 Controls'!$B$5:$B$28,"<>")+COUNTIF('CC4 Controls'!$B$5:$B$19,"<>")+COUNTIF('CC5 Controls'!$B$5:$B$19,"<>")+COUNTIF('CC6 Controls'!$B$5:$B$44,"<>")+COUNTIF('CC7 Controls'!$B$5:$B$30,"<>")+COUNTIF('CC8 Controls'!$B$5:$B$12,"<>")+COUNTIF('CC9 Controls'!$B$5:$B$16,"<>")) - (COUNTIFS('CC1 Controls'!$B$5:$B$39,"<>",'CC1 Controls'!$J$5:$J$39,">=0")+COUNTIFS('CC2 Controls'!$B$5:$B$24,"<>",'CC2 Controls'!$J$5:$J$24,">=0")+COUNTIFS('CC3 Controls'!$B$5:$B$28,"<>",'CC3 Controls'!$J$5:$J$28,">=0")+COUNTIFS('CC4 Controls'!$B$5:$B$19,"<>",'CC4 Controls'!$J$5:$J$19,">=0")+COUNTIFS('CC5 Controls'!$B$5:$B$19,"<>",'CC5 Controls'!$J$5:$J$19,">=0")+COUNTIFS('CC6 Controls'!$B$5:$B$44,"<>",'CC6 Controls'!$J$5:$J$44,">=0")+COUNTIFS('CC7 Controls'!$B$5:$B$30,"<>",'CC7 Controls'!$J$5:$J$30,">=0")+COUNTIFS('CC8 Controls'!$B$5:$B$12,"<>",'CC8 Controls'!$J$5:$J$12,">=0")+COUNTIFS('CC9 Controls'!$B$5:$B$16,"<>",'CC9 Controls'!$J$5:$J$16,">=0"))) -> 1
B39: Total score | C39: =SUMIFS('CC1 Controls'!$J$5:$J$39,'CC1 Controls'!$B$5:$B$39,"<>")+SUMIFS('CC2 Controls'!$J$5:$J$24,'CC2 Controls'!$B$5:$B$24,"<>")+SUMIFS('CC3 Controls'!$J$5:$J$28,'CC3 Controls'!$B$5:$B$28,"<>")+SUMIFS('CC4 Controls'!$J$5:$J$19,'CC4 Controls'!$B$5:$B$19,"<>")+SUMIFS('CC5 Controls'!$J$5:$J$19,'CC5 Controls'!$B$5:$B$19,"<>")+SUMIFS('CC6 Controls'!$J$5:$J$44,'CC6 Controls'!$B$5:$B$44,"<>")+SUMIFS('CC7 Controls'!$J$5:$J$30,'CC7 Controls'!$B$5:$B$30,"<>")+SUMIFS('CC8 Controls'!$J$5:$J$12,'CC8 Controls'!$B$5:$B$12,"<>")+SUMIFS('CC9 Controls'!$J$5:$J$16,'CC9 Controls'!$B$5:$B$16,"<>") -> 139
B40: Maximum possible | C40: =((COUNTIF('CC1 Controls'!$B$5:$B$39,"<>")+COUNTIF('CC2 Controls'!$B$5:$B$24,"<>")+COUNTIF('CC3 Controls'!$B$5:$B$28,"<>")+COUNTIF('CC4 Controls'!$B$5:$B$19,"<>")+COUNTIF('CC5 Controls'!$B$5:$B$19,"<>")+COUNTIF('CC6 Controls'!$B$5:$B$44,"<>")+COUNTIF('CC7 Controls'!$B$5:$B$30,"<>")+COUNTIF('CC8 Controls'!$B$5:$B$12,"<>")+COUNTIF('CC9 Controls'!$B$5:$B$16,"<>")) - (COUNTIFS('CC1 Controls'!$B$5:$B$39,"<>",'CC1 Controls'!$J$5:$J$39,"N/A")+COUNTIFS('CC2 Controls'!$B$5:$B$24,"<>",'CC2 Controls'!$J$5:$J$24,"N/A")+COUNTIFS('CC3 Controls'!$B$5:$B$28,"<>",'CC3 Controls'!$J$5:$J$28,"N/A")+COUNTIFS('CC4 Controls'!$B$5:$B$19,"<>",'CC4 Controls'!$J$5:$J$19,"N/A")+COUNTIFS('CC5 Controls'!$B$5:$B$19,"<>",'CC5 Controls'!$J$5:$J$19,"N/A")+COUNTIFS('CC6 Controls'!$B$5:$B$44,"<>",'CC6 Controls'!$J$5:$J$44,"N/A")+COUNTIFS('CC7 Controls'!$B$5:$B$30,"<>",'CC7 Controls'!$J$5:$J$30,"N/A")+COUNTIFS('CC8 Controls'!$B$5:$B$12,"<>",'CC8 Controls'!$J$5:$J$12,"N/A")+COUNTIFS('CC9 Controls'!$B$5:$B$16,"<>",'CC9 Controls'!$J$5:$J$16,"N/A")))*4 -> 636
B41: Readiness | C41: =IFERROR((SUMIFS('CC1 Controls'!$J$5:$J$39,'CC1 Controls'!$B$5:$B$39,"<>")+SUMIFS('CC2 Controls'!$J$5:$J$24,'CC2 Controls'!$B$5:$B$24,"<>")+SUMIFS('CC3 Controls'!$J$5:$J$28,'CC3 Controls'!$B$5:$B$28,"<>")+SUMIFS('CC4 Controls'!$J$5:$J$19,'CC4 Controls'!$B$5:$B$19,"<>")+SUMIFS('CC5 Controls'!$J$5:$J$19,'CC5 Controls'!$B$5:$B$19,"<>")+SUMIFS('CC6 Controls'!$J$5:$J$44,'CC6 Controls'!$B$5:$B$44,"<>")+SUMIFS('CC7 Controls'!$J$5:$J$30,'CC7 Controls'!$B$5:$B$30,"<>")+SUMIFS('CC8 Controls'!$J$5:$J$12,'CC8 Controls'!$B$5:$B$12,"<>")+SUMIFS('CC9 Controls'!$J$5:$J$16,'CC9 Controls'!$B$5:$B$16,"<>"))/(((COUNTIF('CC1 Controls'!$B$5:$B$39,"<>")+COUNTIF('CC2 Controls'!$B$5:$B$24,"<>")+COUNTIF('CC3 Controls'!$B$5:$B$28,"<>")+COUNTIF('CC4 Controls'!$B$5:$B$19,"<>")+COUNTIF('CC5 Controls'!$B$5:$B$19,"<>")+COUNTIF('CC6 Controls'!$B$5:$B$44,"<>")+COUNTIF('CC7 Controls'!$B$5:$B$30,"<>")+COUNTIF('CC8 Controls'!$B$5:$B$12,"<>")+COUNTIF('CC9 Controls'!$B$5:$B$16,"<>")) - (COUNTIFS('CC1 Controls'!$B$5:$B$39,"<>",'CC1 Controls'!$J$5:$J$39,"N/A")+COUNTIFS('CC2 Controls'!$B$5:$B$24,"<>",'CC2 Controls'!$J$5:$J$24,"N/A")+COUNTIFS('CC3 Controls'!$B$5:$B$28,"<>",'CC3 Controls'!$J$5:$J$28,"N/A")+COUNTIFS('CC4 Controls'!$B$5:$B$19,"<>",'CC4 Controls'!$J$5:$J$19,"N/A")+COUNTIFS('CC5 Controls'!$B$5:$B$19,"<>",'CC5 Controls'!$J$5:$J$19,"N/A")+COUNTIFS('CC6 Controls'!$B$5:$B$44,"<>",'CC6 Controls'!$J$5:$J$44,"N/A")+COUNTIFS('CC7 Controls'!$B$5:$B$30,"<>",'CC7 Controls'!$J$5:$J$30,"N/A")+COUNTIFS('CC8 Controls'!$B$5:$B$12,"<>",'CC8 Controls'!$J$5:$J$12,"N/A")+COUNTIFS('CC9 Controls'!$B$5:$B$16,"<>",'CC9 Controls'!$J$5:$J$16,"N/A")))*4),0) -> 0.21855346 | D41: Total score as a share of the maximum. A blunt but useful single number.
B42: Average level | C42: =IFERROR((SUMIFS('CC1 Controls'!$J$5:$J$39,'CC1 Controls'!$B$5:$B$39,"<>")+SUMIFS('CC2 Controls'!$J$5:$J$24,'CC2 Controls'!$B$5:$B$24,"<>")+SUMIFS('CC3 Controls'!$J$5:$J$28,'CC3 Controls'!$B$5:$B$28,"<>")+SUMIFS('CC4 Controls'!$J$5:$J$19,'CC4 Controls'!$B$5:$B$19,"<>")+SUMIFS('CC5 Controls'!$J$5:$J$19,'CC5 Controls'!$B$5:$B$19,"<>")+SUMIFS('CC6 Controls'!$J$5:$J$44,'CC6 Controls'!$B$5:$B$44,"<>")+SUMIFS('CC7 Controls'!$J$5:$J$30,'CC7 Controls'!$B$5:$B$30,"<>")+SUMIFS('CC8 Controls'!$J$5:$J$12,'CC8 Controls'!$B$5:$B$12,"<>")+SUMIFS('CC9 Controls'!$J$5:$J$16,'CC9 Controls'!$B$5:$B$16,"<>"))/(COUNTIFS('CC1 Controls'!$B$5:$B$39,"<>",'CC1 Controls'!$J$5:$J$39,">=0")+COUNTIFS('CC2 Controls'!$B$5:$B$24,"<>",'CC2 Controls'!$J$5:$J$24,">=0")+COUNTIFS('CC3 Controls'!$B$5:$B$28,"<>",'CC3 Controls'!$J$5:$J$28,">=0")+COUNTIFS('CC4 Controls'!$B$5:$B$19,"<>",'CC4 Controls'!$J$5:$J$19,">=0")+COUNTIFS('CC5 Controls'!$B$5:$B$19,"<>",'CC5 Controls'!$J$5:$J$19,">=0")+COUNTIFS('CC6 Controls'!$B$5:$B$44,"<>",'CC6 Controls'!$J$5:$J$44,">=0")+COUNTIFS('CC7 Controls'!$B$5:$B$30,"<>",'CC7 Controls'!$J$5:$J$30,">=0")+COUNTIFS('CC8 Controls'!$B$5:$B$12,"<>",'CC8 Controls'!$J$5:$J$12,">=0")+COUNTIFS('CC9 Controls'!$B$5:$B$16,"<>",'CC9 Controls'!$J$5:$J$16,">=0")),0) -> 0.87421384
B44: Level 0 — Gap | C44: =COUNTIFS('CC1 Controls'!$B$5:$B$39,"<>",'CC1 Controls'!$J$5:$J$39,0)+COUNTIFS('CC2 Controls'!$B$5:$B$24,"<>",'CC2 Controls'!$J$5:$J$24,0)+COUNTIFS('CC3 Controls'!$B$5:$B$28,"<>",'CC3 Controls'!$J$5:$J$28,0)+COUNTIFS('CC4 Controls'!$B$5:$B$19,"<>",'CC4 Controls'!$J$5:$J$19,0)+COUNTIFS('CC5 Controls'!$B$5:$B$19,"<>",'CC5 Controls'!$J$5:$J$19,0)+COUNTIFS('CC6 Controls'!$B$5:$B$44,"<>",'CC6 Controls'!$J$5:$J$44,0)+COUNTIFS('CC7 Controls'!$B$5:$B$30,"<>",'CC7 Controls'!$J$5:$J$30,0)+COUNTIFS('CC8 Controls'!$B$5:$B$12,"<>",'CC8 Controls'!$J$5:$J$12,0)+COUNTIFS('CC9 Controls'!$B$5:$B$16,"<>",'CC9 Controls'!$J$5:$J$16,0) -> 21
B45: Level 1 — Documented | C45: =COUNTIFS('CC1 Controls'!$B$5:$B$39,"<>",'CC1 Controls'!$J$5:$J$39,1)+COUNTIFS('CC2 Controls'!$B$5:$B$24,"<>",'CC2 Controls'!$J$5:$J$24,1)+COUNTIFS('CC3 Controls'!$B$5:$B$28,"<>",'CC3 Controls'!$J$5:$J$28,1)+COUNTIFS('CC4 Controls'!$B$5:$B$19,"<>",'CC4 Controls'!$J$5:$J$19,1)+COUNTIFS('CC5 Controls'!$B$5:$B$19,"<>",'CC5 Controls'!$J$5:$J$19,1)+COUNTIFS('CC6 Controls'!$B$5:$B$44,"<>",'CC6 Controls'!$J$5:$J$44,1)+COUNTIFS('CC7 Controls'!$B$5:$B$30,"<>",'CC7 Controls'!$J$5:$J$30,1)+COUNTIFS('CC8 Controls'!$B$5:$B$12,"<>",'CC8 Controls'!$J$5:$J$12,1)+COUNTIFS('CC9 Controls'!$B$5:$B$16,"<>",'CC9 Controls'!$J$5:$J$16,1) -> 137
B46: Level 2 — Implemented | C46: =COUNTIFS('CC1 Controls'!$B$5:$B$39,"<>",'CC1 Controls'!$J$5:$J$39,2)+COUNTIFS('CC2 Controls'!$B$5:$B$24,"<>",'CC2 Controls'!$J$5:$J$24,2)+COUNTIFS('CC3 Controls'!$B$5:$B$28,"<>",'CC3 Controls'!$J$5:$J$28,2)+COUNTIFS('CC4 Controls'!$B$5:$B$19,"<>",'CC4 Controls'!$J$5:$J$19,2)+COUNTIFS('CC5 Controls'!$B$5:$B$19,"<>",'CC5 Controls'!$J$5:$J$19,2)+COUNTIFS('CC6 Controls'!$B$5:$B$44,"<>",'CC6 Controls'!$J$5:$J$44,2)+COUNTIFS('CC7 Controls'!$B$5:$B$30,"<>",'CC7 Controls'!$J$5:$J$30,2)+COUNTIFS('CC8 Controls'!$B$5:$B$12,"<>",'CC8 Controls'!$J$5:$J$12,2)+COUNTIFS('CC9 Controls'!$B$5:$B$16,"<>",'CC9 Controls'!$J$5:$J$16,2) -> 1
B47: Level 3 — Evidenced | C47: =COUNTIFS('CC1 Controls'!$B$5:$B$39,"<>",'CC1 Controls'!$J$5:$J$39,3)+COUNTIFS('CC2 Controls'!$B$5:$B$24,"<>",'CC2 Controls'!$J$5:$J$24,3)+COUNTIFS('CC3 Controls'!$B$5:$B$28,"<>",'CC3 Controls'!$J$5:$J$28,3)+COUNTIFS('CC4 Controls'!$B$5:$B$19,"<>",'CC4 Controls'!$J$5:$J$19,3)+COUNTIFS('CC5 Controls'!$B$5:$B$19,"<>",'CC5 Controls'!$J$5:$J$19,3)+COUNTIFS('CC6 Controls'!$B$5:$B$44,"<>",'CC6 Controls'!$J$5:$J$44,3)+COUNTIFS('CC7 Controls'!$B$5:$B$30,"<>",'CC7 Controls'!$J$5:$J$30,3)+COUNTIFS('CC8 Controls'!$B$5:$B$12,"<>",'CC8 Controls'!$J$5:$J$12,3)+COUNTIFS('CC9 Controls'!$B$5:$B$16,"<>",'CC9 Controls'!$J$5:$J$16,3) -> 0
B48: Level 4 — Automated | C48: =COUNTIFS('CC1 Controls'!$B$5:$B$39,"<>",'CC1 Controls'!$J$5:$J$39,4)+COUNTIFS('CC2 Controls'!$B$5:$B$24,"<>",'CC2 Controls'!$J$5:$J$24,4)+COUNTIFS('CC3 Controls'!$B$5:$B$28,"<>",'CC3 Controls'!$J$5:$J$28,4)+COUNTIFS('CC4 Controls'!$B$5:$B$19,"<>",'CC4 Controls'!$J$5:$J$19,4)+COUNTIFS('CC5 Controls'!$B$5:$B$19,"<>",'CC5 Controls'!$J$5:$J$19,4)+COUNTIFS('CC6 Controls'!$B$5:$B$44,"<>",'CC6 Controls'!$J$5:$J$44,4)+COUNTIFS('CC7 Controls'!$B$5:$B$30,"<>",'CC7 Controls'!$J$5:$J$30,4)+COUNTIFS('CC8 Controls'!$B$5:$B$12,"<>",'CC8 Controls'!$J$5:$J$12,4)+COUNTIFS('CC9 Controls'!$B$5:$B$16,"<>",'CC9 Controls'!$J$5:$J$16,4) -> 0
B49: N/A — Not applicable | C49: =COUNTIFS('CC1 Controls'!$B$5:$B$39,"<>",'CC1 Controls'!$J$5:$J$39,"N/A")+COUNTIFS('CC2 Controls'!$B$5:$B$24,"<>",'CC2 Controls'!$J$5:$J$24,"N/A")+COUNTIFS('CC3 Controls'!$B$5:$B$28,"<>",'CC3 Controls'!$J$5:$J$28,"N/A")+COUNTIFS('CC4 Controls'!$B$5:$B$19,"<>",'CC4 Controls'!$J$5:$J$19,"N/A")+COUNTIFS('CC5 Controls'!$B$5:$B$19,"<>",'CC5 Controls'!$J$5:$J$19,"N/A")+COUNTIFS('CC6 Controls'!$B$5:$B$44,"<>",'CC6 Controls'!$J$5:$J$44,"N/A")+COUNTIFS('CC7 Controls'!$B$5:$B$30,"<>",'CC7 Controls'!$J$5:$J$30,"N/A")+COUNTIFS('CC8 Controls'!$B$5:$B$12,"<>",'CC8 Controls'!$J$5:$J$12,"N/A")+COUNTIFS('CC9 Controls'!$B$5:$B$16,"<>",'CC9 Controls'!$J$5:$J$16,"N/A") -> 1
B51: Below level 2 (Type I risk) | C51: =COUNTIFS('CC1 Controls'!$B$5:$B$39,"<>",'CC1 Controls'!$J$5:$J$39,"<2")+COUNTIFS('CC2 Controls'!$B$5:$B$24,"<>",'CC2 Controls'!$J$5:$J$24,"<2")+COUNTIFS('CC3 Controls'!$B$5:$B$28,"<>",'CC3 Controls'!$J$5:$J$28,"<2")+COUNTIFS('CC4 Controls'!$B$5:$B$19,"<>",'CC4 Controls'!$J$5:$J$19,"<2")+COUNTIFS('CC5 Controls'!$B$5:$B$19,"<>",'CC5 Controls'!$J$5:$J$19,"<2")+COUNTIFS('CC6 Controls'!$B$5:$B$44,"<>",'CC6 Controls'!$J$5:$J$44,"<2")+COUNTIFS('CC7 Controls'!$B$5:$B$30,"<>",'CC7 Controls'!$J$5:$J$30,"<2")+COUNTIFS('CC8 Controls'!$B$5:$B$12,"<>",'CC8 Controls'!$J$5:$J$12,"<2")+COUNTIFS('CC9 Controls'!$B$5:$B$16,"<>",'CC9 Controls'!$J$5:$J$16,"<2") -> 158 | D51: Controls that are not yet operating. Each one is a design deficiency in a Type I.
B52: Below level 3 (Type II risk) | C52: =COUNTIFS('CC1 Controls'!$B$5:$B$39,"<>",'CC1 Controls'!$J$5:$J$39,"<3")+COUNTIFS('CC2 Controls'!$B$5:$B$24,"<>",'CC2 Controls'!$J$5:$J$24,"<3")+COUNTIFS('CC3 Controls'!$B$5:$B$28,"<>",'CC3 Controls'!$J$5:$J$28,"<3")+COUNTIFS('CC4 Controls'!$B$5:$B$19,"<>",'CC4 Controls'!$J$5:$J$19,"<3")+COUNTIFS('CC5 Controls'!$B$5:$B$19,"<>",'CC5 Controls'!$J$5:$J$19,"<3")+COUNTIFS('CC6 Controls'!$B$5:$B$44,"<>",'CC6 Controls'!$J$5:$J$44,"<3")+COUNTIFS('CC7 Controls'!$B$5:$B$30,"<>",'CC7 Controls'!$J$5:$J$30,"<3")+COUNTIFS('CC8 Controls'!$B$5:$B$12,"<>",'CC8 Controls'!$J$5:$J$12,"<3")+COUNTIFS('CC9 Controls'!$B$5:$B$16,"<>",'CC9 Controls'!$J$5:$J$16,"<3") -> 159 | D52: Controls operating without retained evidence. Each one will fail a Type II sample.
B55: SCORE BY CRITERION | D55: Bold rows are the criteria; the indented rows beneath are their sub-criteria. All figures are means of the scored controls only — unscored and N/A rows are excluded, so a partly scored plan is not dragged down.
...

Sheet CC1 Controls
A1: CC1 — Control Environment
A2: 28 control activities across CC1.1–CC1.5. Read the scoping note before scoring — it says how each control operates at this headcount. Fill in the shaded columns only.
A4: Ref | B4: Criterion | C4: Control activity | D4: Owner | E4: Frequency | F4: System of record | G4: How to automate it | H4: Evidence artifact | I4: Scoping note at this size | J4: Score | K4: Level | L4: Rationale if N/A | M4: Next due | N4: Owning policy or standard | O4: In the plans? | P4: What the implementation plans say | Q4: What to add to close it
A5: CC1.1 | C5: Integrity and ethical values | J5: =IFERROR(ROUND(AVERAGE(J6:J10),1),"") -> 0 | K5: =IF(COUNT(J6:J10)=0,IF(COUNTIF(J6:J10,"N/A")>0,"all n/a","not scored"),COUNTIF(J6:J10,0)&" gaps, "&COUNTIFS(J6:J10,"<3")&" below 3") -> 5 gaps, 5 below 3 | O5: 1 of 6
A6: CC1.1-01 | B6: CC1.1 | C6: Code of Conduct (POL-COC-001) approved by the Steering Committee and published to all personnel. | D6: CEO | E6: Annual | F6: GitHub + Secureframe | G6: Policy lives in the GitHub policy repo. Approval = a merged pull request approved by the CEO; the merge commit is the dated approval record. Publish the approved PDF to Secureframe > Policies. | H6: Approved policy + merge commit | I6: Applies. Approval is the CEO merging the pull request. A one-person approval is still an approval as long as it is dated and attributable. | J6: 0 | K6: =IF(J6="","",IF(J6="N/A","Not applicable",CHOOSE(J6+1,"Gap","Documented","Implemented","Evidenced","Automated"))) -> Gap | N6: POL-COC-001 (authorised by POL-ISP-001 §13 Annex A) | O6: Partial | P6: ISP plan Phase 1 publishes “all subordinate policies”, but there is no Code of Conduct implementation plan in the set and the Code is never named. | Q6: Create PLN-COC, or add two tasks to ISP plan Phase 1: publish POL-COC-001 by name, and record the Committee approval date and version.
A7: CC1.1-02 | B7: CC1.1 | C7: Every employee and contractor accepts the Code of Conduct at onboarding, on material revision, and annually. | D7: Security Officer | E7: On hire + annual | F7: Secureframe | G7: Secureframe > Policies: assign to the 'employee' and 'contractor' groups. Acceptance tests reset automatically at the annual mark and reminders are sent from the platform. Reset acceptances manually after a material revision. | H7: Acknowledgment register export | I7: Applies to everyone, the CEO included. A two-name acceptance list is still an acceptance list. | J7: 0 | K7: =IF(J7="","",IF(J7="N/A","Not applicable",CHOOSE(J7+1,"Gap","Documented","Implemented","Evidenced","Automated"))) -> Gap | N7: POL-COC-001 §17 + POL-HRS-001 | O7: Partial | P7: ISP plan Phase 2 collects signed policy acknowledgments. Annual re-acceptance and reset on material revision are not stated. | Q7: Add to ISP plan Phase 2: set the annual re-acceptance recurrence in Secureframe, and reset acceptances whenever a policy is materially revised.
A8: CC1.1-03 | B8: CC1.1 | C8: Conflict of interest declaration completed annually and whenever a new client engagement is accepted. | D8: CEO | E8: Annual + per engagement | F8: Secureframe | G8: Add a custom policy document 'Annual COI Declaration' in Secureframe so it inherits the same accept-and-reset workflow. Add a COI line to the engagement intake checklist for the event-driven case. | H8: Signed declarations, incl. 'no conflicts' | I8: Applies, and carries more weight here than at a larger company, because the fractional CISO serves several clients at once. | J8: 0 | K8: =IF(J8="","",IF(J8="N/A","Not applicable",CHOOSE(J8+1,"Gap","Documented","Implemented","Evidenced","Automated"))) -> Gap | N8: POL-COC-001 §7 (no separate POL-COI-001 exists in the library) | O8: No | P8: “Conflict of interest” appears nowhere in the 20 plans. No owning plan exists. | Q8: Create PLN-COI, or add to HRS plan Phase 2: upload the annual conflict confirmation as a policy document in Secureframe so it inherits the accept-and-reset workflow, and stand up the register.
A9: CC1.1-04 | B9: CC1.1 | C9: Ethics reporting channel that bypasses the Security Officer, with anti-retaliation stated. | D9: CEO | E9: Continuous | F9: Google Workspace | G9: Create ethics@prompthalo.com routing only to the CEO. Name it in the Code of Conduct. No tooling needed beyond the alias. Need to be put on the publicly availble web site. | H9: Documented channel + report log or nil return | I9: Applies. The channel must not terminate at the Security Officer. Where the CEO is the only alternative recipient, say exactly that in the Code of Conduct. | J9: 0 | K9: =IF(J9="","",IF(J9="N/A","Not applicable",CHOOSE(J9+1,"Gap","Documented","Implemented","Evidenced","Automated"))) -> Gap | N9: POL-COC-001 §16 + POL-ISP-001 §7 | O9: No | P9: No ethics channel, whistleblowing route or anti-retaliation task in any plan. | Q9: Add to HRS plan Phase 1: create an ethics alias routing only to the CEO, name it in POL-COC-001, and state the anti-retaliation commitment. Record a nil return annually.
A10: CC1.1-05 | B10: CC1.1 | C10: Conduct deviations are documented with the finding, the decision and the rationale. | D10: CEO | E10: As they occur | F10: GitHub Issues | G10: Use a 'conduct' issue label in a private governance repo. Never handle these in email — an auditor cannot sample an inbox. | H10: Case record per event | I10: Applies. Expect a nil return in year one. Record the nil return — an empty file and a clean year look identical to an auditor. | J10: 0 | K10: =IF(J10="","",IF(J10="N/A","Not applicable",CHOOSE(J10+1,"Gap","Documented","Implemented","Evidenced","Automated"))) -> Gap | N10: POL-COC-001 §18 + POL-HRS-001 | O10: Partial | P10: HRS plan Phase 2 defines a sanctions process reference. Nothing requires the finding, decision and rationale to be recorded per event. | Q10: Extend the HRS sanctions task: require a dated record per event capturing the finding, the decision and the rationale, held as a labelled issue in the governance repo, never in email.
A11: CC1.1-06 | B11: CC1.1 | C11: Background screening is completed and recorded for every new starter before access is granted, showing the tier applied, the date completed, the outcome and who authorised access afterwards. | D11: CEO | E11: Per Hire | F11: Secureframe | G11: Enable the background check step in Secureframe > Personnel > Onboarding and connect a screening provider. Completion shows in the personnel view and the record lands in the evidence library. Make it a gate: no AWS or repository access until it passes. Store the outcome only — pass or adjudicated — never the underlying report. | H11: Screening record per hire: tier, date, outcome, authoriser | I11: Applies to contractors as well as employees, with no exception for a founder or a fractional officer. Verify claimed certifications as well as criminal history — misrepresented credentials are the failure mode specific to a security firm, and CISSP and OSCP both verify publicly at no cost. Individualised assessment on any record, never automatic disqualification. | J11: 1 | K11: =IF(J11="","",IF(J11="N/A","Not applicable",CHOOSE(J11+1,"Gap","Documented","Implemented","Evidenced","Automated"))) -> Documented | N11: POL-HRS-001 + STD-SCR-001 (to create) | O11: Yes | P11: HRS plan Phase 1 selects the provider and defines checks per role tier; Phase 3 backfills; screening records per tier are listed as evidence. | Q11: Nothing outstanding. Capture the tier definitions the HRS task produces in STD-SCR-001 so they can change without reissuing a policy.
A12: CC1.2 | C12: Oversight of the control environment | J12: =IFERROR(ROUND(AVERAGE(J14:J19),1),"") -> 1 | K12: =IF(COUNT(J14:J19)=0,IF(COUNTIF(J14:J19,"N/A")>0,"all n/a","not scored"),COUNTIF(J14:J19,0)&" gaps, "&COUNTIFS(J14:J19,"<3")&" below 3") -> 1 gaps, 5 below 3 | O12: 1 of 6
A14: CC1.2-01 | B14: CC1.2 | C14: Governance body defined: the Steering Committee comprises the CEO, satisfied by a dated written record. | D14: Security Officer | E14: Annual | F14: GitHub | G14: Already defined in the POL-ISP-001 Terminology section. Keep the definition in exactly one place and reference it; never restate it per policy. | H14: ISP Terminology entry | I14: Applies. Already satisfied by the Terminology note in POL-ISP-001 defining the Committee as the CEO. | J14: 2 | K14: =IF(J14="","",IF(J14="N/A","Not applicable",CHOOSE(J14+1,"Gap","Documented","Implemented","Evidenced","Automated"))) -> Implemented | N14: POL-ISP-001 §4 (Terminology) | O14: Yes | P14: ISP plan Phase 1 confirms Security Officer appointment and Steering Committee membership in writing. | Q14: Nothing outstanding.
A15: CC1.2-02 | B15: CC1.2 | C15: Every approval, risk acceptance and exception is recorded with the date and the person deciding. | D15: CEO | E15: Continuous | F15: This workbook | G15: Use the Governance Log tab. One line per decision, filled in the same day. This is the single most-requested CC1 artifact and the easiest to lose. | H15: Governance Log | I15: Applies. A dated written note replaces a meeting at this size; the ISP already says so, which is what makes it defensible. | J15: 1 | K15: =IF(J15="","",IF(J15="N/A","Not applicable",CHOOSE(J15+1,"Gap","Documented","Implemented","Evidenced","Automated"))) -> Documented | N15: POL-ISP-001 → Governance Log | O15: Partial | P15: Committee minutes appear in the ISP and Risk plans. No general log of approvals, risk acceptances and exceptions with date and decider. | Q15: Add to ISP plan Phase 1: stand up the Governance Decisions Log covering every approval, risk acceptance, exception and delegation — not only meeting minutes. Use the tab in this workbook.
A16: CC1.2-03 | B16: CC1.2 | C16: The absence of oversight independent of security operations is recorded as a risk with an annual review date. | D16: Security Officer | E16: Annual | F16: Secureframe | G16: Secureframe > Risk Register: one entry, treatment = 'accepted with compensating control', review date set to the annual assessment. | H16: Risk register entry + review note | I16: Applies, and is the control that turns the CC1.2 independence gap into a managed limitation rather than a deficiency. Do not skip it. | J16: 1 | K16: =IF(J16="","",IF(J16="N/A","Not applicable",CHOOSE(J16+1,"Gap","Documented","Implemented","Evidenced","Automated"))) -> Documented | N16: POL-RSK-001 → risk register | O16: Partial | P16: Risk plan builds the register and routes acceptances to the Committee. The independence limitation is not seeded as an entry. | Q16: Add to the Risk plan Phase 1 seeding task: create the independence-limitation entry explicitly, treatment ‘accepted with compensating control’, review date set to the annual assessment.
A17: CC1.2-04 | B17: CC1.2 | C17: CEO reviews and signs the Security Officer's control effectiveness assessment. | D17: CEO | E17: Annual | F17: Word + GitHub | G17: Use the Annual Control Environment Assessment template. One signature covers CC1.2, CC1.3, CC1.4 and CC1.5 — do not split it into four documents. | H17: Signed Annual Assessment | I17: Applies. This is the compensating control for CC1.2 and the reason the size limitation is acceptable. | J17: 1 | K17: =IF(J17="","",IF(J17="N/A","Not applicable",CHOOSE(J17+1,"Gap","Documented","Implemented","Evidenced","Automated"))) -> Documented | N17: POL-ISP-001 §8 → FRM-CE-001 | O17: Partial | P17: ISP plan Phase 3 runs the first control self-assessment and presents it to the Committee. No CEO signature on the Security Officer’s assessment. | Q17: Add to ISP plan Phase 3: the CEO reviews and signs the completed assessment at FRM-CE-001 Section 11. This signature is the CC1.2 compensating control.
A18: CC1.2-05 | B18: CC1.2 | C18: RECOMMENDED — an advisor outside the management reporting line reviews the annual assessment and signs a short oversight memo. | D18: CEO | E18: Annual | F18: Word + GitHub | G18: One unpaid outside advisor, one meeting a year, one signature appended to the Annual Assessment. This is what closes the CC1.2 gap properly. | H18: Advisor oversight memo | I18: Enhancement, not a Trust Services Criteria requirement — the only row in this workbook that is not criterion-mandated. Pre-set to N/A; change it to a score if you appoint an advisor. | J18: N/A | K18: =IF(J18="","",IF(J18="N/A","Not applicable",CHOOSE(J18+1,"Gap","Documented","Implemented","Evidenced","Automated"))) -> Not applicable | L18: Enhancement beyond the Trust Services Criteria; no criterion requires an independent advisor. Recorded as a deliberate scoping decision. Change to a score of 0–4 if an advisor is appointed. | N18: POL-ISP-001 → FRM-CE-001 Annex A | O18: No | P18: No independent advisor task in any plan. Expected — this control is the optional enhancement, not a criterion requirement. | Q18: If adopted: add to ISP plan Phase 3 — appoint the advisor and obtain the oversight memo at FRM-CE-001 Annex A. If declined: record the decision in the Governance Log and score this row N/A.
